[2024-04-23T14:33:54.527+0000] {taskinstance.py:1159} INFO - Dependencies all met for dep_context=non-requeueable deps ti=<TaskInstance: etl.transform manual__2024-04-23T14:33:52.017071+00:00 [queued]>
[2024-04-23T14:33:54.531+0000] {taskinstance.py:1159} INFO - Dependencies all met for dep_context=requeueable deps ti=<TaskInstance: etl.transform manual__2024-04-23T14:33:52.017071+00:00 [queued]>
[2024-04-23T14:33:54.531+0000] {taskinstance.py:1361} INFO - Starting attempt 1 of 1
[2024-04-23T14:33:54.536+0000] {taskinstance.py:1382} INFO - Executing <Task(_PythonDecoratedOperator): transform> on 2024-04-23 14:33:52.017071+00:00
[2024-04-23T14:33:54.539+0000] {standard_task_runner.py:57} INFO - Started process 1873 to run task
[2024-04-23T14:33:54.542+0000] {standard_task_runner.py:84} INFO - Running: ['airflow', 'tasks', 'run', 'etl', 'transform', 'manual__2024-04-23T14:33:52.017071+00:00', '--job-id', '41', '--raw', '--subdir', '/opt/airflow/dags/dags-example/etl.py', '--cfg-path', '/tmp/tmp1jv5ttx_']
[2024-04-23T14:33:54.543+0000] {standard_task_runner.py:85} INFO - Job 41: Subtask transform
[2024-04-23T14:33:54.575+0000] {task_command.py:415} INFO - Running <TaskInstance: etl.transform manual__2024-04-23T14:33:52.017071+00:00 [running]> on host 44f2c0439e04
[2024-04-23T14:33:54.622+0000] {taskinstance.py:1660} INFO - Exporting env vars: AIRFLOW_CTX_DAG_OWNER='airflow' AIRFLOW_CTX_DAG_ID='etl' AIRFLOW_CTX_TASK_ID='transform' AIRFLOW_CTX_EXECUTION_DATE='2024-04-23T14:33:52.017071+00:00' AIRFLOW_CTX_TRY_NUMBER='1' AIRFLOW_CTX_DAG_RUN_ID='manual__2024-04-23T14:33:52.017071+00:00'
[2024-04-23T14:33:54.623+0000] {logging_mixin.py:151} INFO - transform
[2024-04-23T14:33:54.738+0000] {taskinstance.py:1943} ERROR - Task failed with exception
Traceback (most recent call last):
  File "/home/airflow/.local/lib/python3.8/site-packages/fsspec/registry.py", line 226, in get_filesystem_class
    register_implementation(protocol, _import_class(bit["class"]))
  File "/home/airflow/.local/lib/python3.8/site-packages/fsspec/registry.py", line 249, in _import_class
    mod = importlib.import_module(mod)
  File "/usr/local/lib/python3.8/importlib/__init__.py", line 127, in import_module
    return _bootstrap._gcd_import(name[level:], package, level)
  File "<frozen importlib._bootstrap>", line 1014, in _gcd_import
  File "<frozen importlib._bootstrap>", line 991, in _find_and_load
  File "<frozen importlib._bootstrap>", line 973, in _find_and_load_unlocked
ModuleNotFoundError: No module named 's3fs'

The above exception was the direct cause of the following exception:

Traceback (most recent call last):
  File "/home/airflow/.local/lib/python3.8/site-packages/airflow/decorators/base.py", line 221, in execute
    return_value = super().execute(context)
  File "/home/airflow/.local/lib/python3.8/site-packages/airflow/operators/python.py", line 192, in execute
    return_value = self.execute_callable()
  File "/home/airflow/.local/lib/python3.8/site-packages/airflow/operators/python.py", line 209, in execute_callable
    return self.python_callable(*self.op_args, **self.op_kwargs)
  File "/opt/airflow/dags/dags-example/etl.py", line 64, in transform
    data_handler.save_to_parquet(df, partition_cols=partition_cols, cols_dim=cols_dim)
  File "/opt/airflow/./dags/helper/module_2_transform.py", line 24, in save_to_parquet
    df_dim_product.to_parquet('s3://tiki/curated/dim_product',
  File "/home/airflow/.local/lib/python3.8/site-packages/pandas/core/frame.py", line 2889, in to_parquet
    return to_parquet(
  File "/home/airflow/.local/lib/python3.8/site-packages/pandas/io/parquet.py", line 411, in to_parquet
    impl.write(
  File "/home/airflow/.local/lib/python3.8/site-packages/pandas/io/parquet.py", line 161, in write
    path_or_handle, handles, kwargs["filesystem"] = _get_path_or_handle(
  File "/home/airflow/.local/lib/python3.8/site-packages/pandas/io/parquet.py", line 92, in _get_path_or_handle
    fs, path_or_handle = fsspec.core.url_to_fs(
  File "/home/airflow/.local/lib/python3.8/site-packages/fsspec/core.py", line 363, in url_to_fs
    chain = _un_chain(url, kwargs)
  File "/home/airflow/.local/lib/python3.8/site-packages/fsspec/core.py", line 325, in _un_chain
    cls = get_filesystem_class(protocol)
  File "/home/airflow/.local/lib/python3.8/site-packages/fsspec/registry.py", line 228, in get_filesystem_class
    raise ImportError(bit["err"]) from e
ImportError: Install s3fs to access S3
[2024-04-23T14:33:54.749+0000] {taskinstance.py:1400} INFO - Marking task as FAILED. dag_id=etl, task_id=transform, execution_date=20240423T143352, start_date=20240423T143354, end_date=20240423T143354
[2024-04-23T14:33:54.755+0000] {standard_task_runner.py:104} ERROR - Failed to execute job 41 for task transform (Install s3fs to access S3; 1873)
[2024-04-23T14:33:54.772+0000] {local_task_job_runner.py:228} INFO - Task exited with return code 1
[2024-04-23T14:33:54.803+0000] {taskinstance.py:2784} INFO - 0 downstream tasks scheduled from follow-on schedule check
