[2024-04-09T14:26:09.531+0000] {taskinstance.py:1159} INFO - Dependencies all met for dep_context=non-requeueable deps ti=<TaskInstance: dag_setting_v1.get_info manual__2024-04-09T14:26:08.208014+00:00 [queued]>
[2024-04-09T14:26:09.536+0000] {taskinstance.py:1159} INFO - Dependencies all met for dep_context=requeueable deps ti=<TaskInstance: dag_setting_v1.get_info manual__2024-04-09T14:26:08.208014+00:00 [queued]>
[2024-04-09T14:26:09.536+0000] {taskinstance.py:1361} INFO - Starting attempt 1 of 1
[2024-04-09T14:26:09.543+0000] {taskinstance.py:1382} INFO - Executing <Task(_PythonDecoratedOperator): get_info> on 2024-04-09 14:26:08.208014+00:00
[2024-04-09T14:26:09.549+0000] {standard_task_runner.py:57} INFO - Started process 433 to run task
[2024-04-09T14:26:09.552+0000] {standard_task_runner.py:84} INFO - Running: ['airflow', 'tasks', 'run', 'dag_setting_v1', 'get_info', 'manual__2024-04-09T14:26:08.208014+00:00', '--job-id', '11', '--raw', '--subdir', '/opt/airflow/dags/dags-example/first_dag.py', '--cfg-path', '/tmp/tmp28f4esy5']
[2024-04-09T14:26:09.555+0000] {standard_task_runner.py:85} INFO - Job 11: Subtask get_info
[2024-04-09T14:26:09.612+0000] {task_command.py:415} INFO - Running <TaskInstance: dag_setting_v1.get_info manual__2024-04-09T14:26:08.208014+00:00 [running]> on host e1fa9ca99aa3
[2024-04-09T14:26:09.675+0000] {taskinstance.py:1660} INFO - Exporting env vars: AIRFLOW_CTX_DAG_OWNER='airflow' AIRFLOW_CTX_DAG_ID='dag_setting_v1' AIRFLOW_CTX_TASK_ID='get_info' AIRFLOW_CTX_EXECUTION_DATE='2024-04-09T14:26:08.208014+00:00' AIRFLOW_CTX_TRY_NUMBER='1' AIRFLOW_CTX_DAG_RUN_ID='manual__2024-04-09T14:26:08.208014+00:00'
[2024-04-09T14:26:09.677+0000] {taskinstance.py:1943} ERROR - Task failed with exception
Traceback (most recent call last):
  File "/home/airflow/.local/lib/python3.8/site-packages/airflow/decorators/base.py", line 221, in execute
    return_value = super().execute(context)
  File "/home/airflow/.local/lib/python3.8/site-packages/airflow/operators/python.py", line 192, in execute
    return_value = self.execute_callable()
  File "/home/airflow/.local/lib/python3.8/site-packages/airflow/operators/python.py", line 209, in execute_callable
    return self.python_callable(*self.op_args, **self.op_kwargs)
  File "/opt/airflow/dags/dags-example/first_dag.py", line 14, in get_info
    module_1()
TypeError: 'module' object is not callable
[2024-04-09T14:26:09.687+0000] {taskinstance.py:1400} INFO - Marking task as FAILED. dag_id=dag_setting_v1, task_id=get_info, execution_date=20240409T142608, start_date=20240409T142609, end_date=20240409T142609
[2024-04-09T14:26:09.694+0000] {standard_task_runner.py:104} ERROR - Failed to execute job 11 for task get_info ('module' object is not callable; 433)
[2024-04-09T14:26:09.725+0000] {local_task_job_runner.py:228} INFO - Task exited with return code 1
[2024-04-09T14:26:09.739+0000] {taskinstance.py:2784} INFO - 0 downstream tasks scheduled from follow-on schedule check
